<?xml version="1.0" encoding="utf-8"?>
<mujoco model="index_finger">
    <!--–––– general
    settings ––––-->
    <compiler angle="degree" />
    <option timestep="0.001" />
    <option gravity="0 0 0" />

    <!--––––
    visual assets ––––-->
    <asset>
        <mesh name="base_link_mesh"
            file="/Users/cheng.zhang/Desktop/Finger_Aloha_MJ/meshes/base_link.STL" />
        <mesh name="proximal_link_mesh"
            file="/Users/cheng.zhang/Desktop/Finger_Aloha_MJ/meshes/proximal_link.STL" />
        <mesh name="distal_link_mesh"
            file="/Users/cheng.zhang/Desktop/Finger_Aloha_MJ/meshes/distal_link.STL" />
        <material name="finger_grey" rgba=".79 .82 .93 1" />

        <!--Fancy
        stuff-->
        <texture name="floor_tex" type="2d"
            builtin="checker" width="512" height="512"
            rgb1="0.12 0.19 0.30"
            rgb2="0.16 0.25 0.38"
            mark="cross" markrgb="0.9 0.9 0.9" />

        <material name="floor_mat" texture="floor_tex" texuniform="true"
            reflectance="0.05" texrepeat="20 20"
            specular="0.3" shininess="40" />
    </asset>

    <!--––––
    soft, high-friction default contact ––––-->
    <default>
        <geom type="mesh" material="finger_grey"
            margin="0.001" gap="0"
            condim="3"
            solref="0.005 1"
            solimp="0.9 0.95 0.002"
            friction="2 0.002 0.0001" />
        <joint type="hinge" damping="0.05" />
    </default>

    <!--––––
    kinematic tree ––––-->
    <worldbody>
        <!-- finger base -->
        <body name="base_link" pos="0 0 0" euler="-90 0 0">
            <inertial pos="-0.012424 -3.3888e-05 -1.0216e-18"
                mass="0.043213"
                diaginertia="7.1934e-06 1.1994e-05 1.0845e-05" />
            <geom mesh="base_link_mesh" />

            <!-- proximal phalanx -->
            <body name="proximal_link">
                <joint name="proximal_joint" pos="0 0 0"
                    axis="0 0 1" range="0 90" />

                <inertial pos="0.030014 -0.0008083 0.00066078"
                    mass="0.024623"
                    diaginertia="3.8829e-06 5.649e-06 4.0093e-06" />
                <geom mesh="proximal_link_mesh" />

                <body name="proxi_exo1" pos="0.03 -0.01 0" euler="90 0 0">
                    <geom type="capsule"
                        fromto="0 0 0   -.012 0 .005"
                        size="0.003"
                        rgba="0 0 1 1" />

                    <body name="proxi_exo2" pos="-0.012 0 0.005">
                        <joint name="hinge2.1" type="hinge" pos="0 0 0" axis="0 1 0" range="0 90" />
                        <geom type="capsule"
                            fromto="0 0 0   0.013 0 .048"
                            size="0.003"
                            rgba="0 0 1 1" />
                    </body>
                </body>
                <!-- distal phalanx -->
                <body name="distal_link" pos="0.04883 0 0">
                    <joint name="distal_joint" pos="0 0 0"
                        axis="0 0 1" range="0 90" />

                    <inertial pos="0.025976 -0.00040286 0.00046448"
                        mass="0.030476"
                        diaginertia="4.1504e-06 4.0525e-06 3.52e-06" />
                    <geom mesh="distal_link_mesh" />

                    <body name="distal_exo1" pos="0.022 -0.012 0" euler="90 0 0">
                        <geom type="capsule"
                            fromto="0 0 0   .014 0 .013"
                            size="0.003"
                            rgba="0 0 1 1" />
                        <body name="distal_exo2" pos="0.014 0 .013">
                            <joint name="hinge1.1" type="hinge" pos="0 0 0"
                                axis="0 1 0" range="0 360" />
                            <geom type="capsule"
                                fromto="0 0 0   -0.01 0 .075"
                                size="0.003"
                                rgba="0 0 1 1" />
                            <body name="distal_exo3" pos="-0.01 0 .075">
                                <joint name="hinge1.2" type="hinge" pos="0 0 0"
                                    axis="0 1 0" range="0 360" />
                                <geom type="capsule"
                                    fromto="0 0 0   -0.007 0 -.025"
                                    size="0.003"
                                    rgba="0 0 1 1" />
                            </body>
                        </body>
                    </body>

                    <!-- fingertip contact & marker -->
                    <site name="fingertip" pos="0.04883 0.01 0"
                        size="0.005" rgba="0 1 0 1" type="sphere" />
                    <geom name="tip_sphere" type="sphere" size="0.005"
                        pos="0.04883 0.01 0"
                        condim="3"
                        friction="2 0.002 0.0001" />
                </body>
            </body>
        </body>

        <!-- 1  proximal link : total length 0.035 m -->
        <body name="shell_prox" pos="0 0 0.07">
            <joint type="free" />
            <inertial pos="0 0 0"
                mass="0.00716"
                diaginertia="2.29e-07 8.45e-07 8.45e-07" />
            <geom type="capsule"
                fromto="-0.0175 0 0   0.0175 0 0"
                size="0.008" rgba="1 0.8 0.6 0.6"
                contype="0" conaffinity="0" />
        </body>

        <!-- 2  middle link : length 0.025 m -->
        <body name="shell_mid" pos="0.035 0 0.07">
            <joint type="free" />
            <inertial pos="0 0 0"
                mass="0.00376"
                diaginertia="9.20e-08 2.42e-07 2.42e-07" />
            <geom type="capsule"
                fromto="-0.0125 0 0   0.0125 0 0"
                size="0.007" rgba="1 0.8 0.6 0.6"
                contype="0" conaffinity="0" />
        </body>

        <!-- 3  distal link : length 0.020 m -->
        <body name="shell_dist" pos="0.060 0 0.07">
            <joint type="free" />
            <inertial pos="0 0 0"
                mass="0.00217"
                diaginertia="3.91e-08 9.19e-08 9.19e-08" />
            <geom type="capsule"
                fromto="-0.01 0 0   0.01 0 0"
                size="0.006" rgba="1 0.8 0.6 0.6"
                contype="0" conaffinity="0" />
        </body>

        <geom name="ground" type="plane"
            pos="0 0 -0.2" size="10 10 0.1"
            material="floor_mat" />

        <!-- Light -->
        <light name="key" pos="0 0 3" dir="0 0 -1" directional="true"
            diffuse="0.7 0.7 0.7" specular="0.3 0.3 0.3" />
        <light name="fill" pos="3 3 2" dir="-1 -1 -0.5" directional="true"
            diffuse="0.3 0.3 0.3" specular="0.1 0.1 0.1" />

    </worldbody>

    <contact>
        <exclude body1="base_link" body2="proximal_link" />
        <exclude body1="proximal_link" body2="distal_link" />
    </contact>

    <equality>
        <!-- <weld name="w1" body1="distal_exo3" body2="shell_dist"
            solref="0.003 2" solimp="0.9 0.95 0.002" /> -->
        <!-- <weld name="w2" body1="proxi_exo2" body2="shell_mid"
            solref="0.003 2" solimp="0.9 0.95 0.002" /> -->
        <weld name="w3" body1="shell_mid" body2="shell_dist"
            solref="0.002 2" solimp="0.9 0.95 0.002" />
        <weld name="w4" body1="shell_prox" body2="shell_mid"
            solref="0.002 2" solimp="0.9 0.95 0.002" />
    </equality>

    <!--––––
    sensors ––––-->
    <sensor>
        <force site="fingertip" name="tip_force" />
    </sensor>
</mujoco>