<mujoco model="index_finger">
  <compiler angle="degree"/>
  <option timestep="0.001" gravity="0 0 0"/>
  <default>
    <default class="/">
      <joint type="hinge" damping="0.050000000000000003"/>
      <geom type="mesh" condim="3" material="finger_grey" friction="2 0.002 0.0001" solref="0.0050000000000000001 1" solimp="0.90000000000000002 0.94999999999999996 0.002" margin="0.001" gap="0"/>
    </default>
  </default>
  <asset>
    <mesh name="base_link_mesh" class="/" file="base_link-4e8fe9c740a6efdc8830f001839e381d2b2bb55e.STL"/>
    <mesh name="proximal_link_mesh" class="/" file="proximal_link-9dbbc95285b1363426dfabfb3290e004782f4ee2.STL"/>
    <mesh name="distal_link_mesh" class="/" file="distal_link-d223021ed1ed8eea1aa53b7e42a553def7ab2d20.STL"/>
    <material name="finger_grey" class="/" rgba="0.79000000000000004 0.81999999999999995 0.93000000000000005 1"/>
    <texture name="floor_tex" type="2d" builtin="checker" rgb1="0.12 0.19 0.29999999999999999" rgb2="0.16 0.25 0.38" mark="cross" markrgb="0.90000000000000002 0.90000000000000002 0.90000000000000002" width="512" height="512"/>
    <material name="floor_mat" class="/" texture="floor_tex" texrepeat="20 20" texuniform="true" specular="0.29999999999999999" shininess="40" reflectance="0.050000000000000003"/>
  </asset>
  <worldbody>
    <body name="base_link" pos="0 0 0" euler="-90 0 0">
      <inertial pos="-0.012423999999999999 -3.3887999999999998e-05 -1.0216e-18" mass="0.043213000000000001" diaginertia="7.1933999999999996e-06 1.1994000000000001e-05 1.0845e-05"/>
      <geom name="//unnamed_geom_0" class="/" mesh="base_link_mesh"/>
      <body name="proximal_link">
        <joint name="proximal_joint" class="/" pos="0 0 0" axis="0 0 1" range="-10 90"/>
        <inertial pos="0.030013999999999999 -0.00080829999999999997 0.00066078000000000003" mass="0.024622999999999999" diaginertia="3.8828999999999997e-06 5.6489999999999996e-06 4.0092999999999999e-06"/>
        <geom name="//unnamed_geom_1" class="/" mesh="proximal_link_mesh"/>
        <body name="proxi_exo1" pos="0.029999999999999999 -0.01 0" euler="90 0 0">
          <geom name="//unnamed_geom_2" class="/" type="capsule" size="0.0030000000000000001" rgba="0 0 1 1" fromto="0 0 0 -0.012 0 0.0050000000000000001"/>
          <body name="proxi_exo2" pos="-0.012 0 0.0050000000000000001">
            <joint name="hinge2.1" class="/" type="hinge" pos="0 0 0" axis="0 1 0" range="-20 90"/>
            <geom name="//unnamed_geom_3" class="/" type="capsule" size="0.0030000000000000001" rgba="0 0 1 1" fromto="0 0 0 0.012999999999999999 0 0.051999999999999998"/>
          </body>
        </body>
        <body name="distal_link" pos="0.048829999999999998 0 0">
          <joint name="distal_joint" class="/" pos="0 0 0" axis="0 0 1" range="-10 90"/>
          <inertial pos="0.025975999999999999 -0.00040286 0.00046448000000000003" mass="0.030476" diaginertia="4.1504000000000001e-06 4.0524999999999997e-06 3.5200000000000002e-06"/>
          <geom name="//unnamed_geom_4" class="/" mesh="distal_link_mesh"/>
          <body name="distal_R_dummy" pos="0.02 -0.01 0" euler="-90 -180 180">
            <site name="distal_R_site" class="/" size="0.001" pos="0 0 0"/>
            <geom name="//unnamed_geom_5" class="/" type="sphere" size="0.001" pos="0 0 0"/>
          </body>
          <body name="distal_exo1" pos="0.021999999999999999 -0.012 0" euler="90 0 0">
            <geom name="//unnamed_geom_6" class="/" type="capsule" size="0.0030000000000000001" rgba="0 0 1 1" fromto="0 0 0 0.014 0 0.012999999999999999"/>
            <body name="distal_exo2" pos="0.014 0 0.012999999999999999">
              <joint name="hinge1.1" class="/" type="hinge" pos="0 0 0" axis="0 1 0" range="0 360"/>
              <geom name="//unnamed_geom_7" class="/" type="capsule" size="0.0030000000000000001" rgba="0 0 1 1" fromto="0 0 0 -0.014293999999999999 0 0.095175999999999997"/>
              <body name="distal_exo3" pos="-0.014293999999999999 0 0.095175999999999997">
                <joint name="hinge1.2" class="/" type="hinge" pos="0 0 0" axis="0 1 0" range="0 360"/>
                <geom name="//unnamed_geom_8" class="/" type="capsule" size="0.0030000000000000001" rgba="0 0 1 1" fromto="0 0 0 -0.0070000000000000001 0 -0.050000000000000003"/>
                <body name="dist_H_dummy" pos="-0.0070000000000000001 0 -0.050000000000000003">
                  <site name="distal_H_site" class="/" size="0.001" pos="0 0 0"/>
                  <geom name="//unnamed_geom_9" class="/" type="sphere" size="0.001" pos="0 0 0"/>
                </body>
              </body>
            </body>
          </body>
          <body name="fingertip" pos="0.048829999999999998 0.01 0">
            <site name="fingertip" class="/" type="capsule" rgba="0 1 0 1" size="0.0050000000000000001" fromto="-0.01 0 0 0.012999999999999999 0 0" pos="0 0 0"/>
            <geom name="tip_sphere" class="/" type="capsule" condim="3" size="0.0050000000000000001" rgba="0 1 0 1" friction="2 0.002 0.0001" fromto="-0.01 0 0 0.012999999999999999 0 0" pos="0 0 0"/>
          </body>
        </body>
      </body>
    </body>
    <body name="shell_prox" mocap="true" pos="0 0 0.070000000000000007">
      <inertial pos="0 0 0" mass="0.0071599999999999997" diaginertia="2.29e-07 8.4499999999999996e-07 8.4499999999999996e-07"/>
      <geom name="//unnamed_geom_11" class="/" type="capsule" contype="0" conaffinity="0" size="0.0080000000000000002" rgba="1 0.80000000000000004 0.59999999999999998 0.59999999999999998" fromto="-0.017500000000000002 0 0 0.017500000000000002 0 0"/>
    </body>
    <body name="shell_mid" mocap="true" pos="0.035000000000000003 0 0.070000000000000007">
      <inertial pos="0 0 0" mass="0.0037599999999999999" diaginertia="9.2000000000000003e-08 2.4200000000000002e-07 2.4200000000000002e-07"/>
      <geom name="//unnamed_geom_12" class="/" type="capsule" contype="0" conaffinity="0" size="0.0070000000000000001" rgba="1 0.80000000000000004 0.59999999999999998 0.59999999999999998" fromto="-0.012500000000000001 0 0 0.012500000000000001 0 0"/>
    </body>
    <body name="shell_dist" mocap="true" pos="0.059999999999999998 0 0.070000000000000007">
      <inertial pos="0 0 0" mass="0.0021700000000000001" diaginertia="3.9099999999999999e-08 9.1899999999999996e-08 9.1899999999999996e-08"/>
      <geom name="//unnamed_geom_13" class="/" type="capsule" contype="0" conaffinity="0" size="0.0060000000000000001" rgba="1 0.80000000000000004 0.59999999999999998 0.59999999999999998" fromto="-0.01 0 0 0.01 0 0"/>
    </body>
    <body name="ground" pos="0 0 -0.059999999999999998">
      <geom name="ground" class="/" type="plane" size="10 10 0.10000000000000001" material="floor_mat" pos="0 0 0"/>
    </body>
    <light name="key" class="/" directional="true" pos="0 0 3" dir="0 0 -1" diffuse="0.69999999999999996 0.69999999999999996 0.69999999999999996" specular="0.29999999999999999 0.29999999999999999 0.29999999999999999"/>
    <light name="fill" class="/" directional="true" pos="3 3 2" dir="-1 -1 -0.5" diffuse="0.29999999999999999 0.29999999999999999 0.29999999999999999" specular="0.10000000000000001 0.10000000000000001 0.10000000000000001"/>
  </worldbody>
  <contact>
    <exclude name="//unnamed_contact_0" body1="base_link" body2="proximal_link"/>
    <exclude name="//unnamed_contact_1" body1="proximal_link" body2="distal_link"/>
  </contact>
  <equality>
    <weld name="w1" class="/" solref="0.002 2" solimp="0.90000000000000002 0.94999999999999996 0.002" body1="distal_exo3" body2="shell_dist"/>
    <weld name="w2" class="/" solref="0.002 2" solimp="0.90000000000000002 0.94999999999999996 0.002" body1="proxi_exo2" body2="shell_mid"/>
  </equality>
  <sensor>
    <touch name="tip_force" site="fingertip"/>
    <torque name="dist_R" site="distal_R_site"/>
    <torque name="dist_H" site="distal_H_site"/>
  </sensor>
</mujoco>
